---
id: 异常
title: 本文内容
sidebar_label: 异常
---



## 抛异常

```
raise Exception
raise Exception('错误信息')
```

> - 直接 `raise 异常类`，会自动创建一个 Exception 对象
> - 或者直接抛出一个我们自己创建的 Exception 对象



## 常见的异常

| 类名              | 描述                                                         |
| ----------------- | ------------------------------------------------------------ |
| Exception         | 几乎所有的异常类都是从它派生而来的                           |
| AttributeError    | 引用属性或给它赋值失败时引发                                 |
| OSError           | 操作系统不能执行指定的任务(如打开文件)时引发，有多个子类     |
| IndexError        | 使用序列中不存在的索引时引发，为LookupError的子类            |
| KeyError          | 使用映射中不存在的键时引发，为LookupError的子类              |
| NameError         | 找不到名称(变量)时引发                                       |
| SyntaxError       | 代码不正确时引发                                             |
| TypeError         | 将内置操作或函数用于类型不正确的对象时引发                   |
| ValueError        | 将内置操作或函数用于这样的对象时引发:其类型正确但包含的值不合适 |
| ZeroDivisionError | 在除法或求模运算的第二个参数为零时引发                       |



## 自定义异常

```
class SomeCustomException(Exception): pass
```

> 直接或者间接继承了 Exception 类即可



## 捕获异常

```
try:
    a = 5
    b = 0
    print(a / b)
except ZeroDivisionError as e:
    print(e)
```

> - try except 捕获异常
> - as e 这一段可以去掉（如果我们不需要使用到这个异常对象的话）



## 异常上下文

```
try:
    a = 5
    b = 0
    print(a / b)
except ZeroDivisionError as e:
    raise ValueError
```

输出

```
Traceback (most recent call last):
  File "/Users/czp/workspace/projects/python-demo/test.py", line 4, in <module>
    print(a / b)
ZeroDivisionError: division by zero

During handling of the above exception, another exception occurred:

Traceback (most recent call last):
  File "/Users/czp/workspace/projects/python-demo/test.py", line 6, in <module>
    raise ValueError
ValueError
```

虽然我们捕获了异常，但是又抛出了另一个异常，这时候被捕获的异常作为异常上下文会被输出。

我们可以自定义异常上下文，使用 raise from

```
try:
    a = 5
    b = 0
    print(a / b)
except ZeroDivisionError as e:
    raise ValueError from Exception
```

输出

```
Exception

The above exception was the direct cause of the following exception:

Traceback (most recent call last):
  File "/Users/czp/workspace/projects/python-demo/test.py", line 6, in <module>
    raise ValueError from Exception
ValueError
```

如果我们想抛弃异常上下文，就可以使用 raise Exception from None

```
try:
    a = 5
    b = 0
    print(a / b)
except ZeroDivisionError as e:
    raise ValueError from None
```

输出

```
Traceback (most recent call last):
  File "/Users/czp/workspace/projects/python-demo/test.py", line 6, in <module>
    raise ValueError from None
ValueError
```



## 多个 except

```
try:
    a = 5
    b = 0
    print(a / b)
except ZeroDivisionError as e:
    raise ValueError from None
except ValueError as e:
    raise ValueError from None
```

> 跟 java 的差不多



## 同时处理多种异常

```
try:
    a = 5
    b = 0
    print(a / b)
except (ZeroDivisionError, ValueError) as e:
    raise ValueError from None
```

> 也跟 java 的 e1 | e2 | e3 语法差不多



## try except else

有些情况下，在没有出现异常时执行一个代码块很有用。可像条件语句和循环一样，给 try/except 语句添加一个 else 子句

```
try:
    a = 5
    b = 0
    print(a / b)
except:
    print('抛异常了')
else:
    print('没抛异常')
```

> 如果将 b 修改为非0数字，将会运行到 else 子句
>
> python 有很多这种一切顺利就运行 else 的情况



## finally

```
try:
    a = 5
    b = 0
    print(a / b)
except:
    print('抛异常了')
else:
    print('没抛异常')
finally:
    print('一定会执行，除非程序退出了')
```

> 跟 java 的一个样

